# Using traceback

# Write a function divide_numbers that takes two arguments and divides the first number by the second.
# If a ZeroDivisionError exception occurs, catch it and print the stack trace using the traceback module.

### üá∫üá¶ Ukrainian version:

# –í–∏–∫–æ—Ä–∏—Å—Ç–∞–Ω–Ω—è traceback

# –ù–∞–ø–∏—à—ñ—Ç—å —Ñ—É–Ω–∫—Ü—ñ—é divide_numbers, —è–∫–∞ –ø—Ä–∏–π–º–∞—î –¥–≤–∞ –∞—Ä–≥—É–º–µ–Ω—Ç–∏ —Ç–∞ –¥—ñ–ª–∏—Ç—å –ø–µ—Ä—à–µ —á–∏—Å–ª–æ –Ω–∞ –¥—Ä—É–≥–µ.
# –Ø–∫—â–æ –≤–∏–Ω–∏–∫–∞—î –≤–∏–∫–ª—é—á–µ–Ω–Ω—è ZeroDivisionError, –ø–µ—Ä–µ—Ö–æ–ø—ñ—Ç—å –π–æ–≥–æ —ñ –≤–∏–≤–µ–¥—ñ—Ç—å —Å—Ç–µ–∫-—Ç—Ä–µ–π—Å, –≤–∏–∫–æ—Ä–∏—Å—Ç–æ–≤—É—é—á–∏ –º–æ–¥—É–ª—å traceback.

# Write your code here
import traceback

def divide_numbers(a, b):
    try:
        return a / b
    except ZeroDivisionError:
        print("An exception occurred: ")
        traceback.print_exc()

divide_numbers(1, 0)
